<?xml version="1.0" encoding="utf-8"?>
<!-- =================================================================================== -->
<!-- |    This document was autogenerated by xacro from ur5e_robot.urdf.xacro          | -->
<!-- |    EDITING THIS FILE BY HAND IS NOT RECOMMENDED                                 | -->
<!-- =================================================================================== -->
<robot name="ur5e_robotiq85">

  <!--################################################
  ########              arm                    #######
  ####################################################-->

  <link name="base_link">
    <visual>
      <geometry>
        <mesh filename="./visual/base.dae"/>
      </geometry>
      <material name="LightGrey">
        <color rgba="0.7 0.7 0.7 1.0"/>
      </material>
    </visual>
    <collision>
      <geometry>
        <mesh filename="./collision/base.stl" scale="1.0 1.0 1.0"/>
      </geometry>
    </collision>
    <inertial>
      <mass value="4.0"/>
      <origin rpy="0 0 0" xyz="0.0 0.0 0.0"/>
      <inertia ixx="0.00443333156" ixy="0.0" ixz="0.0" iyy="0.00443333156" iyz="0.0" izz="0.0072"/>
    </inertial>
  </link>
  <joint name="shoulder_pan_joint" type="revolute">
    <parent link="base_link"/>
    <child link="shoulder_link"/>
    <origin rpy="0.0 0.0 0.0" xyz="0.0 0.0 0.163"/>
    <axis xyz="0 0 1"/>
    <limit effort="150.0" lower="-6.28318530718" upper="6.28318530718" velocity="3.14"/>
    <dynamics damping="0.0" friction="0.0"/>
  </joint>
  <link name="shoulder_link">
    <visual>
      <geometry>
        <mesh filename="./visual/shoulder.dae"/>
      </geometry>
      <material name="LightGrey">
        <color rgba="0.7 0.7 0.7 1.0"/>
      </material>
    </visual>
    <collision>
      <geometry>
        <mesh filename="./collision/shoulder.stl" scale="1.0 1.0 1.0"/>
      </geometry>
    </collision>
    <inertial>
      <mass value="3.7"/>
      <origin rpy="0 0 0" xyz="0.0 0.0 0.0"/>
      <inertia ixx="0.010267495893" ixy="0.0" ixz="0.0" iyy="0.010267495893" iyz="0.0" izz="0.00666"/>
    </inertial>
  </link>
  <joint name="shoulder_lift_joint" type="revolute">
    <parent link="shoulder_link"/>
    <child link="upper_arm_link"/>
    <origin rpy="0.0 1.57079632679 0.0" xyz="0.0 0.138 0.0"/>
    <axis xyz="0 1 0"/>
    <limit effort="150.0" lower="-6.28318530718" upper="6.28318530718" velocity="3.14"/>
    <dynamics damping="0.0" friction="0.0"/>
  </joint>
  <link name="upper_arm_link">
    <visual>
      <geometry>
        <mesh filename="./visual/upperarm.dae"/>
      </geometry>
      <material name="LightGrey">
        <color rgba="0.7 0.7 0.7 1.0"/>
      </material>
    </visual>
    <collision>
      <geometry>
        <mesh filename="./collision/upperarm.stl" scale="1.0 1.0 1.0"/>
      </geometry>
    </collision>
    <inertial>
      <mass value="8.393"/>
      <origin rpy="0 0 0" xyz="0.0 0.0 0.2125"/>
      <inertia ixx="0.133885781862" ixy="0.0" ixz="0.0" iyy="0.133885781862" iyz="0.0" izz="0.0151074"/>
    </inertial>
  </link>
  <joint name="elbow_joint" type="revolute">
    <parent link="upper_arm_link"/>
    <child link="forearm_link"/>
    <origin rpy="0.0 0.0 0.0" xyz="0.0 -0.131 0.425"/>
    <axis xyz="0 1 0"/>
    <limit effort="150.0" lower="-3.14159265359" upper="3.14159265359" velocity="3.14"/>
    <dynamics damping="0.0" friction="0.0"/>
  </joint>
  <link name="forearm_link">
    <visual>
      <geometry>
        <mesh filename="./visual/forearm.dae"/>
      </geometry>
      <material name="LightGrey">
        <color rgba="0.7 0.7 0.7 1.0"/>
      </material>
    </visual>
    <collision>
      <geometry>
        <mesh filename="./collision/forearm.stl" scale="1.0 1.0 1.0"/>
      </geometry>
    </collision>
    <inertial>
      <mass value="2.275"/>
      <origin rpy="0 0 0" xyz="0.0 0.0 0.196"/>
      <inertia ixx="0.0311796208615" ixy="0.0" ixz="0.0" iyy="0.0311796208615" iyz="0.0" izz="0.004095"/>
    </inertial>
  </link>
  <joint name="wrist_1_joint" type="revolute">
    <parent link="forearm_link"/>
    <child link="wrist_1_link"/>
    <origin rpy="0.0 1.57079632679 0.0" xyz="0.0 0.0 0.392"/>
    <axis xyz="0 1 0"/>
    <limit effort="28.0" lower="-6.28318530718" upper="6.28318530718" velocity="6.28"/>
    <dynamics damping="0.0" friction="0.0"/>
  </joint>
  <link name="wrist_1_link">
    <visual>
      <geometry>
        <mesh filename="./visual/wrist1.dae"/>
      </geometry>
      <material name="LightGrey">
        <color rgba="0.7 0.7 0.7 1.0"/>
      </material>
    </visual>
    <collision>
      <geometry>
        <mesh filename="./collision/wrist1.stl" scale="1.0 1.0 1.0"/>
      </geometry>
    </collision>
    <inertial>
      <mass value="1.219"/>
      <origin rpy="0 0 0" xyz="0.0 0.127 0.0"/>
      <inertia ixx="0.00255989897604" ixy="0.0" ixz="0.0" iyy="0.00255989897604" iyz="0.0" izz="0.0021942"/>
    </inertial>
  </link>
  <joint name="wrist_2_joint" type="revolute">
    <parent link="wrist_1_link"/>
    <child link="wrist_2_link"/>
    <origin rpy="0.0 0.0 0.0" xyz="0.0 0.127 0.0"/>
    <axis xyz="0 0 1"/>
    <limit effort="28.0" lower="-6.28318530718" upper="6.28318530718" velocity="6.28"/>
    <dynamics damping="0.0" friction="0.0"/>
  </joint>
  <link name="wrist_2_link">
    <visual>
      <geometry>
        <mesh filename="./visual/wrist2.dae"/>
      </geometry>
      <material name="LightGrey">
        <color rgba="0.7 0.7 0.7 1.0"/>
      </material>
    </visual>
    <collision>
      <geometry>
        <mesh filename="./collision/wrist2.stl" scale="1.0 1.0 1.0"/>
      </geometry>
    </collision>
    <inertial>
      <mass value="1.219"/>
      <origin rpy="0 0 0" xyz="0.0 0.0 0.1"/>
      <inertia ixx="0.00255989897604" ixy="0.0" ixz="0.0" iyy="0.00255989897604" iyz="0.0" izz="0.0021942"/>
    </inertial>
  </link>
  <joint name="wrist_3_joint" type="revolute">
    <parent link="wrist_2_link"/>
    <child link="wrist_3_link"/>
    <origin rpy="0.0 0.0 0.0" xyz="0.0 0.0 0.1"/>
    <axis xyz="0 1 0"/>
    <limit effort="28.0" lower="-6.28318530718" upper="6.28318530718" velocity="6.28"/>
    <dynamics damping="0.0" friction="0.0"/>
  </joint>
  <link name="wrist_3_link">
    <visual>
      <geometry>
        <mesh filename="./visual/wrist3.dae"/>
      </geometry>
      <material name="LightGrey">
        <color rgba="0.7 0.7 0.7 1.0"/>
      </material>
    </visual>
    <collision>
      <geometry>
        <mesh filename="./collision/wrist3.stl" scale="1.0 1.0 1.0"/>
      </geometry>
    </collision>
    <inertial>
      <mass value="0.1879"/>
      <origin rpy="1.57079632679 0 0" xyz="0.0 0.0771 0.0"/>
      <inertia ixx="9.89041005217e-05" ixy="0.0" ixz="0.0" iyy="9.89041005217e-05" iyz="0.0" izz="0.0001321171875"/>
    </inertial>
  </link>
  <joint name="ee_fixed_joint" type="fixed">
    <parent link="wrist_3_link"/>
    <child link="ee_link"/>
<!--    <origin rpy="0.0 0.0 1.57079632679" xyz="0.0 0.1 0.0"/>-->
    <origin rpy="-1.57079632679 0.0 0.0" xyz="0.0 0.1 0.0"/>
  </joint>
  <link name="ee_link">
    <collision>
      <geometry>
        <box size="0.01 0.01 0.01"/>
      </geometry>
      <origin rpy="0 0 0" xyz="-0.01 0 0"/>
    </collision>
  </link>

  <transmission name="shoulder_pan_trans">
    <type>transmission_interface/SimpleTransmission</type>
    <joint name="shoulder_pan_joint">
      <hardwareInterface>hardware_interface/PositionJointInterface</hardwareInterface>
    </joint>
    <actuator name="shoulder_pan_motor">
      <mechanicalReduction>1</mechanicalReduction>
    </actuator>
  </transmission>
  <transmission name="shoulder_lift_trans">
    <type>transmission_interface/SimpleTransmission</type>
    <joint name="shoulder_lift_joint">
      <hardwareInterface>hardware_interface/PositionJointInterface</hardwareInterface>
    </joint>
    <actuator name="shoulder_lift_motor">
      <mechanicalReduction>1</mechanicalReduction>
    </actuator>
  </transmission>
  <transmission name="elbow_trans">
    <type>transmission_interface/SimpleTransmission</type>
    <joint name="elbow_joint">
      <hardwareInterface>hardware_interface/PositionJointInterface</hardwareInterface>
    </joint>
    <actuator name="elbow_motor">
      <mechanicalReduction>1</mechanicalReduction>
    </actuator>
  </transmission>
  <transmission name="wrist_1_trans">
    <type>transmission_interface/SimpleTransmission</type>
    <joint name="wrist_1_joint">
      <hardwareInterface>hardware_interface/PositionJointInterface</hardwareInterface>
    </joint>
    <actuator name="wrist_1_motor">
      <mechanicalReduction>1</mechanicalReduction>
    </actuator>
  </transmission>
  <transmission name="wrist_2_trans">
    <type>transmission_interface/SimpleTransmission</type>
    <joint name="wrist_2_joint">
      <hardwareInterface>hardware_interface/PositionJointInterface</hardwareInterface>
    </joint>
    <actuator name="wrist_2_motor">
      <mechanicalReduction>1</mechanicalReduction>
    </actuator>
  </transmission>
  <transmission name="wrist_3_trans">
    <type>transmission_interface/SimpleTransmission</type>
    <joint name="wrist_3_joint">
      <hardwareInterface>hardware_interface/PositionJointInterface</hardwareInterface>
    </joint>
    <actuator name="wrist_3_motor">
      <mechanicalReduction>1</mechanicalReduction>
    </actuator>
  </transmission>
  <gazebo reference="shoulder_link">
    <selfCollide>true</selfCollide>
  </gazebo>
  <gazebo reference="upper_arm_link">
    <selfCollide>true</selfCollide>
  </gazebo>
  <gazebo reference="forearm_link">
    <selfCollide>true</selfCollide>
  </gazebo>
  <gazebo reference="wrist_1_link">
    <selfCollide>true</selfCollide>
  </gazebo>
  <gazebo reference="wrist_3_link">
    <selfCollide>true</selfCollide>
  </gazebo>
  <gazebo reference="wrist_2_link">
    <selfCollide>true</selfCollide>
  </gazebo>
  <gazebo reference="ee_link">
    <selfCollide>true</selfCollide>
  </gazebo>

  <!--################################################
  ########              gripper                  #####
  ####################################################-->
  <!--  Begin Robotiq-85-->
  <link name="robotiq_arg2f_base_link">
    <visual>
<!--      <origin rpy="0 1.5708 0" xyz="0 0 0"/>-->
      <geometry>
        <mesh filename="./robotiq_85_gripper/visual/robotiq_85_base_link.dae"/>
      </geometry>
    </visual>
    <collision>
<!--      <origin rpy="0 1.5708 0" xyz="0 0 0"/>-->
      <geometry>
        <mesh filename="./robotiq_85_gripper/collision/robotiq_85_base_link.stl"/>
      </geometry>
    </collision>
    <inertial>
      <mass value="0.636951" />
      <origin xyz="0.0 0.0 0.0" />
      <inertia ixx = "0.000380" ixy = "0.000000" ixz = "0.000000"
           iyx = "0.000000" iyy = "0.001110" iyz = "0.000000"
           izx = "0.000000" izy = "0.000000" izz = "0.001171" />
    </inertial>
  </link>
  <link name="robotiq_85_left_knuckle_link">
    <visual>
      <geometry>
        <mesh filename="./robotiq_85_gripper/visual/robotiq_85_knuckle_link.dae"/>
      </geometry>
    </visual>
<!--    <collision>-->
<!--      <geometry>-->
<!--        <mesh filename="./robotiq_85_gripper/collision/robotiq_85_knuckle_link.stl"/>-->
<!--      </geometry>-->
<!--    </collision>-->
    <inertial>
      <mass value="0.018491" />
      <origin xyz="0.0 0.0 0.0" />
      <inertia ixx = "0.000009" ixy = "-0.000001" ixz = "0.000000"
           iyx = "-0.000001" iyy = "0.000001" iyz = "0.000000"
           izx = "0.000000" izy = "0.000000" izz = "0.000010" />
    </inertial>
  </link>
  <link name="robotiq_85_left_inner_knuckle_link">
    <visual>
      <geometry>
        <mesh filename="./robotiq_85_gripper/visual/robotiq_85_inner_knuckle_link.dae"/>
      </geometry>
    </visual>
<!--    <collision>-->
<!--      <geometry>-->
<!--        <mesh filename="./robotiq_85_gripper/collision/robotiq_85_inner_knuckle_link.stl"/>-->
<!--      </geometry>-->
<!--    </collision>-->
    <inertial>
      <mass value="0.029951" />
      <origin xyz="0.0 0.0 0.0" />
      <inertia ixx = "0.000039" ixy = "0.000000" ixz = "0.000000"
           iyx = "0.000000" iyy = "0.000005" iyz = "0.000000"
           izx = "0.000000" izy = "0.000000" izz = "0.000035" />
    </inertial>
  </link>
  <link name="robotiq_85_right_knuckle_link">
    <visual>
      <geometry>
        <mesh filename="./robotiq_85_gripper/visual/robotiq_85_knuckle_link.dae"/>
      </geometry>
    </visual>
<!--    <collision>-->
<!--      <geometry>-->
<!--        <mesh filename="./robotiq_85_gripper/collision/robotiq_85_knuckle_link.stl"/>-->
<!--      </geometry>-->
<!--    </collision>-->
    <inertial>
      <mass value="0.018491" />
      <origin xyz="0.0 0.0 0.0" />
      <inertia ixx = "0.000009" ixy = "-0.000001" ixz = "0.000000"
           iyx = "-0.000001" iyy = "0.000001" iyz = "0.000000"
           izx = "0.000000" izy = "0.000000" izz = "0.000010" />
    </inertial>
  </link>
  <link name="robotiq_85_left_finger_link">
    <visual>
      <geometry>
        <mesh filename="./robotiq_85_gripper/visual/robotiq_85_finger_link.dae"/>
      </geometry>
    </visual>
<!--    <collision>-->
<!--      <geometry>-->
<!--        <mesh filename="./robotiq_85_gripper/collision/robotiq_85_finger_link.stl"/>-->
<!--      </geometry>-->
<!--    </collision>-->
    <inertial>
      <mass value="0.027309" />
      <origin xyz="0.0 0.0 0.0" />
      <inertia ixx = "0.000003" ixy = "-0.000002" ixz = "0.000000"
           iyx = "-0.000002" iyy = "0.000021" iyz = "0.000000"
           izx = "0.000000" izy = "0.000000" izz = "0.000020" />
    </inertial>
  </link>
  <link name="robotiq_85_right_finger_link">
    <visual>
      <geometry>
        <mesh filename="./robotiq_85_gripper/visual/robotiq_85_finger_link.dae"/>
      </geometry>
    </visual>
<!--    <collision>-->
<!--      <geometry>-->
<!--        <mesh filename="./robotiq_85_gripper/collision/robotiq_85_finger_link.stl"/>-->
<!--      </geometry>-->
<!--    </collision>-->
    <inertial>
      <mass value="0.027309" />
      <origin xyz="0.0 0.0 0.0" />
      <inertia ixx = "0.000003" ixy = "-0.000002" ixz = "0.000000"
           iyx = "-0.000002" iyy = "0.000021" iyz = "0.000000"
           izx = "0.000000" izy = "0.000000" izz = "0.000020" />
    </inertial>
  </link>
  <link name="robotiq_85_right_inner_knuckle_link">
    <visual>
      <geometry>
        <mesh filename="./robotiq_85_gripper/visual/robotiq_85_inner_knuckle_link.dae"/>
      </geometry>
    </visual>
<!--    <collision>-->
<!--      <geometry>-->
<!--        <mesh filename="./robotiq_85_gripper/collision/robotiq_85_inner_knuckle_link.stl"/>-->
<!--      </geometry>-->
<!--    </collision>-->
    <inertial>
      <mass value="0.029951" />
      <origin xyz="0.0 0.0 0.0" />
      <inertia ixx = "0.000039" ixy = "0.000000" ixz = "0.000000"
           iyx = "0.000000" iyy = "0.000005" iyz = "0.000000"
           izx = "0.000000" izy = "0.000000" izz = "0.000035" />
    </inertial>
  </link>
  <link name="robotiq_85_left_finger_tip_link">
    <visual>
<!--      <origin xyz="0.006 0.018 0"/>-->
      <geometry>
        <mesh filename="./robotiq_85_gripper/visual/robotiq_85_finger_tip_link.dae"/>
      </geometry>
    </visual>
<!--    <collision>-->
<!--&lt;!&ndash;      <origin xyz="0.006 0.018 0"/>&ndash;&gt;-->
<!--      <geometry>-->
<!--        <mesh filename="./robotiq_85_gripper/collision/robotiq_85_finger_tip_link.stl"/>-->
<!--      </geometry>-->
<!--    </collision>-->
    <inertial>
      <mass value="0.019555" />
      <origin xyz="0.0 0.0 0.0" />
      <inertia ixx = "0.000002" ixy = "0.000000" ixz = "0.000000"
           iyx = "0.000000" iyy = "0.000005" iyz = "0.000000"
           izx = "0.000000" izy = "0.000000" izz = "0.000006" />
    </inertial>
  </link>
  <link name="robotiq_85_right_finger_tip_link">
    <visual>
<!--      <origin xyz="0.006 0.018 0"/>-->
      <geometry>
        <mesh filename="./robotiq_85_gripper/visual/robotiq_85_finger_tip_link.dae"/>
      </geometry>
    </visual>
<!--    <collision>-->
<!--&lt;!&ndash;      <origin xyz="0.006 0.018 0"/>&ndash;&gt;-->
<!--      <geometry>-->
<!--        <mesh filename="./robotiq_85_gripper/collision/robotiq_85_finger_tip_link.stl"/>-->
<!--      </geometry>-->
<!--    </collision>-->
    <inertial>
      <mass value="0.019555" />
      <origin xyz="0.0 0.0 0.0" />
      <inertia ixx = "0.000002" ixy = "0.000000" ixz = "0.000000"
           iyx = "0.000000" iyy = "0.000005" iyz = "0.000000"
           izx = "0.000000" izy = "0.000000" izz = "0.000006" />
    </inertial>
  </link>
  <link name="left_inner_finger_pad">
    <visual>
      <origin rpy="0 0 0" xyz="0 0 0"/>
      <geometry>
        <box size="0.038 0.008 0.02"/>
      </geometry>
      <material name="">
        <color rgba="0.9 0.9 0.9 1"/>
      </material>
    </visual>
    <collision>
      <origin rpy="0 0 0" xyz="0 0 0"/>
      <geometry>
        <box size="0.038 0.008 0.002"/>
      </geometry>
      <material name="">
        <color rgba="0.9 0.9 0.9 1"/>
      </material>
    </collision>
  </link>
  <link name="right_inner_finger_pad">
    <visual>
      <origin rpy="0 0 0" xyz="0 0 0"/>
      <geometry>
        <box size="0.038 0.008 0.02"/>
      </geometry>
      <material name="">
        <color rgba="0.9 0.9 0.9 1"/>
      </material>
    </visual>
    <collision>
      <origin rpy="0 0 0" xyz="0 0 0"/>
      <geometry>
        <box size="0.038 0.008 0.02"/>
      </geometry>
      <material name="">
        <color rgba="0.9 0.0 0.0 1"/>
      </material>
    </collision>
  </link>

<!--  <joint name="robotiq_85_left_knuckle_joint" type="revolute">-->
<!--    <parent link="robotiq_arg2f_base_link"/>-->
<!--    <child link="robotiq_85_left_knuckle_link"/>-->
<!--    <axis xyz="0 0 1"/>-->
<!--    <origin rpy="3.14 0.0 0.0" xyz="0.05490451627 0.03060114443 0.0"/>-->
<!--    <limit lower="0.0" upper="0.80285" velocity="3.14" effort="1000"/>-->
<!--  </joint>-->
<!--  <joint name="robotiq_85_left_finger_joint" type="fixed">-->
<!--    <parent link="robotiq_85_left_knuckle_link"/>-->
<!--    <child link="robotiq_85_left_finger_link"/>-->
<!--    <origin xyz="-0.00408552455 -0.03148604435 0.0" rpy="0 0 0" />-->
<!--  </joint>-->
<!--  <joint name="robotiq_85_left_inner_knuckle_joint" type="revolute">-->
<!--    <parent link="robotiq_arg2f_base_link"/>-->
<!--    <child link="robotiq_85_left_inner_knuckle_link"/>-->
<!--    <axis xyz="0 0 1"/>-->
<!--    <origin xyz="0.06142 0.0127 0" rpy="3.14 0.0 0.0" />-->
<!--    <limit lower="-3.14" upper="3.14" velocity="3.14" effort="0.1"/>-->
<!--    <mimic joint="robotiq_85_left_knuckle_joint" offset="0"/>-->
<!--  </joint>-->
<!--  <joint name="robotiq_85_left_finger_tip_joint" type="revolute">-->
<!--    <parent link="robotiq_85_left_inner_knuckle_link"/>-->
<!--    <child link="robotiq_85_left_finger_tip_link"/>-->
<!--    <axis xyz="0 0 1"/>-->
<!--    <origin xyz="0.04303959807 -0.03759940821 0.0" rpy="0.0 0.0 0.0"/>-->
<!--    <limit lower="-3.14" upper="3.14" velocity="3.14" effort="0.1"/>-->
<!--    <mimic joint="robotiq_85_left_knuckle_joint" multiplier="-1"/>-->
<!--  </joint>-->
<!--  <joint name="robotiq_85_right_knuckle_joint" type="revolute">-->
<!--    <parent link="robotiq_arg2f_base_link"/>-->
<!--    <child link="robotiq_85_right_knuckle_link"/>-->
<!--    <axis xyz="0 0 1"/>-->
<!--    <origin rpy="0.0 0.0 0.0" xyz="0.05490451627 -0.03060114443 0.0"/>-->
<!--    <limit lower="-3.14" upper="3.14" velocity="3.14" effort="1000"/>-->
<!--    <mimic joint="robotiq_85_left_knuckle_joint"/>-->
<!--  </joint>-->
<!--  <joint name="robotiq_85_right_finger_joint" type="fixed">-->
<!--    <parent link="robotiq_85_right_knuckle_link"/>-->
<!--    <child link="robotiq_85_right_finger_link"/>-->
<!--    <origin xyz="-0.00408552455 -0.03148604435 0.0" rpy="0 0 0" />-->
<!--  </joint>-->
<!--  <joint name="robotiq_85_right_inner_knuckle_joint" type="revolute">-->
<!--    <parent link="robotiq_arg2f_base_link"/>-->
<!--    <child link="robotiq_85_right_inner_knuckle_link"/>-->
<!--    <axis xyz="0 0 1"/>-->
<!--    <origin xyz="0.06142 -0.0127 0" rpy="0 0 0"/>-->
<!--    <limit lower="-3.14" upper="3.14" velocity="3.14" effort="0.1"/>-->
<!--    <mimic joint="robotiq_85_left_knuckle_joint" offset="0"/>-->
<!--  </joint>-->
<!--  <joint name="robotiq_85_right_finger_tip_joint" type="revolute">-->
<!--    <parent link="robotiq_85_right_inner_knuckle_link"/>-->
<!--    <child link="robotiq_85_right_finger_tip_link"/>-->
<!--    <axis xyz="0 0 1"/>-->
<!--    <origin rpy="0.0 0.0 0.0" xyz="0.04303959807 -0.03759940821  0.0"/>-->
<!--    <limit lower="-3.14" upper="3.14" velocity="3.14" effort="0.1"/>-->
<!--    <mimic joint="robotiq_85_left_knuckle_joint" multiplier="-1"/>-->
<!--  </joint>-->

  <joint name="robotiq_2f_85_left_driver_joint" type="prismatic">
    <origin rpy="3.1416 0 0" xyz="0.14 0.045 0"/>
    <parent link="robotiq_arg2f_base_link"/>
    <child link="left_inner_finger_pad"/>
    <axis xyz="0.45 1.7 0"/>
    <limit effort="1000" lower="0" upper="0.044" velocity="2.0"/>
  </joint>
  <joint name="robotiq_2f_85_right_driver_joint" type="prismatic">
    <origin rpy="0 0 0" xyz="0.14 -0.045 0"/>
    <parent link="robotiq_arg2f_base_link"/>
    <child link="right_inner_finger_pad"/>
    <axis xyz="0.45 1.7 0"/>
    <limit effort="1000" lower="0" upper="0.044" velocity="2.0"/>
  </joint>

  <joint name="robotiq_2f_85_left_pad_joint" type="fixed">
    <origin rpy="0 0 0" xyz="-0.025 -0.005 0"/>
    <parent link="left_inner_finger_pad"/>
    <child link="robotiq_85_left_finger_tip_link"/>
    <axis xyz="0 0 1"/>
  </joint>
  <joint name="robotiq_2f_85_right_pad_joint" type="fixed">
    <origin rpy="0 0 0" xyz="-0.025 -0.005 0"/>
    <parent link="right_inner_finger_pad"/>
    <child link="robotiq_85_right_finger_tip_link"/>
    <axis xyz="0 0 1"/>
  </joint>

<!--  <joint name="robotiq_85_left_knuckle_joint" type="revolute">-->
<!--    <parent link="robotiq_arg2f_base_link"/>-->
<!--    <child link="robotiq_85_left_knuckle_link"/>-->
<!--    <axis xyz="0 0 1"/>-->
<!--    <origin rpy="3.14 0.0 0.0" xyz="0.05490451627 0.03060114443 0.0"/>-->
<!--    <limit lower="0.0" upper="0.8" velocity="2.0" effort="10"/>-->
<!--    <mimic joint="finger_joint" multiplier="-1" offset="0"/>-->
<!--  </joint>-->
  <joint name="robotiq_85_left_knuckle_joint" type="fixed">
    <parent link="robotiq_arg2f_base_link"/>
    <child link="robotiq_85_left_knuckle_link"/>
    <axis xyz="0 0 1"/>
    <origin rpy="3.14 0.0 0.0" xyz="0.05490451627 0.03060114443 0.0"/>
<!--    <limit lower="0.0" upper="0.8" velocity="2.0" effort="10"/>-->
<!--    <mimic joint="finger_joint" multiplier="-1" offset="0"/>-->
  </joint>

  <joint name="robotiq_85_left_finger_joint" type="fixed">
    <parent link="robotiq_85_left_knuckle_link"/>
    <child link="robotiq_85_left_finger_link"/>
    <axis xyz="0 0 1"/>
    <origin xyz="-0.00408552455 -0.03148604435 0.0" rpy="0 0 0" />
  </joint>
<!--  <joint name="robotiq_85_left_inner_knuckle_joint" type="revolute">-->
<!--    <parent link="robotiq_arg2f_base_link"/>-->
<!--    <child link="robotiq_85_left_inner_knuckle_link"/>-->
<!--    <axis xyz="0 0 1"/>-->
<!--    <origin xyz="0.06142 0.0127 0" rpy="3.14 0.0 0.0" />-->
<!--    <limit lower="0" upper="0.8" velocity="2.0" effort="10" />-->
<!--    <mimic joint="finger_joint" multiplier="-1" offset="0"/>-->
<!--  </joint>-->
  <joint name="robotiq_85_left_inner_knuckle_joint" type="fixed">
    <parent link="robotiq_arg2f_base_link"/>
    <child link="robotiq_85_left_inner_knuckle_link"/>
    <axis xyz="0 0 1"/>
    <origin xyz="0.06142 0.0127 0" rpy="3.14 0.0 0.0" />
<!--    <limit lower="0" upper="0.8" velocity="2.0" effort="10" />-->
<!--    <mimic joint="finger_joint" multiplier="-1" offset="0"/>-->
  </joint>
<!--  <joint name="robotiq_85_left_finger_tip_joint" type="revolute">-->
<!--    <parent link="robotiq_85_left_inner_knuckle_link"/>-->
<!--    <child link="robotiq_85_left_finger_tip_link"/>-->
<!--    <axis xyz="0 0 1"/>-->
<!--    <origin xyz="0.04303959807 -0.03759940821 0.0" rpy="0.0 0.0 0.0"/>-->
<!--    <limit lower="-3.14" upper="3.14" velocity="2.0" effort="10"/>-->
<!--    <mimic joint="robotiq_85_left_knuckle_joint" multiplier="-1"/>-->
<!--  </joint>-->
<!--  <joint name="robotiq_85_left_finger_tip_joint" type="revolute">-->
<!--    <parent link="robotiq_85_left_finger_link"/>-->
<!--    <child link="robotiq_85_left_finger_tip_link"/>-->
<!--    <axis xyz="0 0 1"/>-->
<!--&lt;!&ndash;    <origin xyz="0.04303959807 -0.03759940821 0.0" rpy="0.0 0.0 0.0"/>&ndash;&gt;-->
<!--&lt;!&ndash;    <origin xyz="0.053 0.012 0.0" rpy="0.0 0.0 0.0"/>&ndash;&gt;-->
<!--    <origin xyz="0.047 -0.006 0.0" rpy="0.0 0.0 0.0"/>-->
<!--    <limit lower="-0.8" upper="0" velocity="2.0" effort="10"/>&ndash;&gt;-->
<!--    <mimic joint="finger_joint" multiplier="1" offset="0"/>-->
<!--  </joint>-->
<!--  <joint name="robotiq_85_right_knuckle_joint" type="revolute">-->
<!--    <parent link="robotiq_arg2f_base_link"/>-->
<!--    <child link="robotiq_85_right_knuckle_link"/>-->
<!--    <axis xyz="0 0 1"/>-->
<!--    <origin rpy="0.0 0.0 0.0" xyz="0.05490451627 -0.03060114443 0.0"/>-->
<!--    <limit lower="0.0" upper="0.8" velocity="2.0" effort="10"/>-->
<!--    <mimic joint="finger_joint" multiplier="-1" offset="0"/>-->
<!--  </joint>-->
  <joint name="robotiq_85_right_knuckle_joint" type="fixed">
    <parent link="robotiq_arg2f_base_link"/>
    <child link="robotiq_85_right_knuckle_link"/>
    <axis xyz="0 0 1"/>
    <origin rpy="0.0 0.0 0.0" xyz="0.05490451627 -0.03060114443 0.0"/>
<!--    <limit lower="0.0" upper="0.8" velocity="2.0" effort="10"/>-->
<!--    <mimic joint="finger_joint" multiplier="-1" offset="0"/>-->
  </joint>
  <joint name="robotiq_85_right_finger_joint" type="fixed">
    <parent link="robotiq_85_right_knuckle_link"/>
    <child link="robotiq_85_right_finger_link"/>
    <axis xyz="0 0 1"/>
    <origin xyz="-0.00408552455 -0.03148604435 0.0" rpy="0 0 0" />
  </joint>
<!--  <joint name="robotiq_85_right_inner_knuckle_joint" type="revolute">-->
<!--    <parent link="robotiq_arg2f_base_link"/>-->
<!--    <child link="robotiq_85_right_inner_knuckle_link"/>-->
<!--    <axis xyz="0 0 1"/>-->
<!--    <origin xyz="0.06142 -0.0127 0" rpy="0 0 0"/>-->
<!--    <limit lower="0" upper="0.8" velocity="2.0" effort="10" />-->
<!--    <mimic joint="finger_joint" multiplier="-1" offset="0"/>-->
<!--  </joint>-->
  <joint name="robotiq_85_right_inner_knuckle_joint" type="fixed">
    <parent link="robotiq_arg2f_base_link"/>
    <child link="robotiq_85_right_inner_knuckle_link"/>
    <axis xyz="0 0 1"/>
    <origin xyz="0.06142 -0.0127 0" rpy="0 0 0"/>
<!--    <limit lower="0" upper="0.8" velocity="2.0" effort="10" />-->
<!--    <mimic joint="finger_joint" multiplier="-1" offset="0"/>-->
  </joint>
<!--  <joint name="robotiq_85_right_finger_tip_joint" type="revolute">-->
<!--    <parent link="robotiq_85_right_inner_knuckle_link"/>-->
<!--    <child link="robotiq_85_right_finger_tip_link"/>-->
<!--    <axis xyz="0 0 1"/>-->
<!--    <origin xyz="0.04303959807 -0.03759940821 0.0" rpy="0.0 0.0 0.0"/>-->
<!--    <limit lower="-3.14" upper="3.14" velocity="2.0" effort="10"/>-->
<!--    <mimic joint="robotiq_85_left_knuckle_joint" multiplier="-1"/>-->
<!--  </joint>-->
<!--  <joint name="robotiq_85_right_finger_tip_joint" type="revolute">-->
<!--    <parent link="robotiq_85_right_finger_link"/>-->
<!--    <child link="robotiq_85_right_finger_tip_link"/>-->
<!--    <axis xyz="0 0 1"/>-->
<!--&lt;!&ndash;    <origin rpy="0.0 0.0 0.0" xyz="0.04303959807 -0.03759940821  0.0"/>&ndash;&gt;-->
<!--&lt;!&ndash;    <origin xyz="0.053 0.012 0.0" rpy="0.0 0.0 0.0"/>&ndash;&gt;-->
<!--    <origin xyz="0.047 -0.006 0.0" rpy="0.0 0.0 0.0"/>-->
<!--    <limit lower="-0.8" upper="0" velocity="2.0" effort="10"/>&ndash;&gt;-->
<!--    <mimic joint="finger_joint" multiplier="1" offset="0"/>-->
<!--  </joint>-->


  <!-- Frame coincident with all-zeros TCP on UR controller -->
  <link name="grasp_convenient_link"/>
  <joint name="grasp_convenient_joint" type="fixed">
    <origin rpy="0 0 3.1416" xyz="0 0 0.16"/>
<!--    <origin rpy="0 0 3.1416" xyz="0 0 0.22"/>-->
    <parent link="ee_link"/>
    <child link="grasp_convenient_link"/>
  </joint>
<!--  <link name="grasp_convenient_link"/>-->
<!--  <joint name="wrist_3_link-tool0_fixed_joint" type="fixed">-->
<!--    <origin rpy="-1.57079632679 0 0" xyz="0 0.1 0"/>-->
<!--    <parent link="wrist_3_link"/>-->
<!--    <child link="grasp_convenient_link"/>-->
<!--  </joint>-->

  <!-- ROS base_link to UR 'Base' Coordinates transform -->
  <link name="base"/>
  <joint name="base_link-base_fixed_joint" type="fixed">
    <!-- NOTE: this rotation is only needed as long as base_link itself is
                 not corrected wrt the real robot (ie: rotated over 180
                 degrees)
      -->
    <origin rpy="0 0 -3.14159265359" xyz="0 0 0"/>
    <parent link="base_link"/>
    <child link="base"/>
  </joint>

  <link name="world"/>
  <joint name="world_joint" type="fixed">
    <parent link="world"/>
    <child link="base_link"/>
    <origin rpy="0.0 0.0 -1.57" xyz="0.0 0.0 0.0"/>
  </joint>

  <!-- connect gripper to arm -->
  <joint name="arm_gripper_joint" type="fixed">
    <parent link="ee_link"/>
    <child link="robotiq_arg2f_base_link"/>
    <origin rpy="0 -1.5708 -1.5708" xyz="0.0 0.0 0.0"/>
<!--    <origin rpy="0 0 -1.5708" xyz="0.0 0.0 0.0"/>-->
  </joint>

  <!-- eye-in-hand camera -->
  <joint name="realsense_hand_joint" type="fixed">
<!--    <origin rpy="0.035 0.019 0.062" xyz="-0.032 -0.064 -0.115"/>-->
<!--    <origin rpy="0 0 0" xyz="-0.032 -0.064 -0.115"/>-->
    <origin rpy="0 0 0" xyz="-0.032 -0.064 -0.15"/>
<!--    <origin rpy="0 0 0" xyz="-0.0251 -0.0658 -0.10"/>-->
<!--    <origin rpy="0 0 0" xyz="-0.0251 -0.1178 -0.21"/>-->
<!--    <origin rpy="0.02081 0.01433 0.05247" xyz="-0.0251 -0.0658 -0.10"/>-->
    <parent link="grasp_convenient_link"/>
    <child link="camera_hand_color_frame"/>
  </joint>
  <link name="camera_hand_link">
    <visual>
      <origin rpy="1.5707963267948966 0 1.5707963267948966" xyz="0.00987 -0.02 -0.02"/>
      <geometry>
        <mesh filename="realsense2_description/meshes/d415.stl"/>
      </geometry>
      <material name="aluminum">
        <color rgba="0.5 0.5 0.5 1"/>
      </material>
    </visual>
    <collision>
      <origin rpy="0 0 0" xyz="0 -0.02 0"/>
      <geometry>
        <box size="0.02005 0.099 0.023"/>
      </geometry>
    </collision>
    <inertial>
      <mass value="0.564"/>
      <origin xyz="0 0 0"/>
      <inertia ixx="0.003881243" ixy="0.0" ixz="0.0" iyy="0.000498940" iyz="0.0" izz="0.003879257"/>
    </inertial>
  </link>
  <!-- camera color joints and links -->
  <joint name="camera_hand_color_joint" type="fixed">
<!--    <origin xyz="0 -0.015 0" rpy="0 0 0"/>-->
<!--    <origin xyz="0 -0.015 0" rpy="0 -1.57 1.57"/>-->
    <origin xyz="0 0 0" rpy="0 -1.57 1.57"/>
    <parent link="camera_hand_color_frame"/>
    <child link="camera_hand_link"/>
  </joint>
  <link name="camera_hand_color_frame"/>

  <joint name="camera_hand_color_optical_joint" type="fixed">
    <origin xyz="0 0 0" rpy="-1.571 -0.000 -1.571"/>
<!--    <origin xyz="0 0 0" rpy="0 0 0"/>-->
    <parent link="camera_hand_color_frame"/>
    <child link="camera_hand_color_optical_frame"/>
  </joint>
  <link name="camera_hand_color_optical_frame"/>
  <!-- Only used when processing real point cloud since it requires camera_hand_depth_optical_frame -->
  <joint name="camera_hand_depth_optical_joint" type="fixed">
    <origin xyz="-0.000 -0.015 -0.000" rpy="-1.573 0.003 -1.576"/>
    <parent link="camera_hand_color_frame"/>
    <child link="camera_hand_depth_optical_frame"/>
  </joint>
  <link name="camera_hand_depth_optical_frame"/>

</robot>